Workbook
Name Product_list: IFERROR(_xlfn._xlws.FILTER('Overview EII'!$B$45:$B$95,'Overview EII'!$A$45:$A$95=Summary!$B$6),"Select sector first")

Sheet Overview EII
A1: Tool to support the calculation of GHG emission avoidance from energy intensive industry (EII) projects under the Innovation Fund (v7.0 | 03.12.2025)
A3: Introduction to the calculation tool
A4: This tool supports the calculation of GHG emission avoidance from projects in energy intensive industries under the Innovation Fund (IF), including carbon capture and utilisation (CCU), production of biofuels, and substitute products. The absolute GHG emission avoidance of a project applying for the IF is calculated by comparing a scenario including the proposed project with a reference scenario without the project. The reference scenario includes the alternative process(es) that produce products that provide the same or equivalent function(s) as the project’s product(s) in the absence of the project.
A5: For further detailed information on how to do the calculation and on all conditions linked to the application and grant award, please refer to the Call Text and the Methodology for GHG Emission Avoidance Calculations. This tool is provided only as support. In case of divergence of the information or formulas between this tool and the Call Text and the Methodology, the latter texts take precedence.
A7: Using the spreadsheet
A9: The cells are color-coded to guide the user. Captions are on the sheets where data entry is required.
A11: Colour code
A12: Enter data
A13: Calculated data
A14: Select an option
A15: Please provide additional information
A16: No data entry required
... A20: The spreadsheet is divided into tabs according to its contents and purposes
A21: Overview EII | B21: Provides an overview of the spreadsheet for monitoring and reporting GHG avoided during the project's operation.
A22: Summary | B22: Presents a summary of the absolute and relative greenhouse gas emissions avoidance. Note that this sheet is protected to reduce the risk of accidental errors being introduced.
A23: Summary per year | B23: Presents a summary of the absolute and relative greenhouse gas emissions avoidance on a yearly basis, as well as the difference between the reported and the estimated values. Note that this sheet is protected to reduce the risk of accidental errors being introduced.
A24: Reference emissions EII | B24: Contains data and calculation of greenhouse gas emissions related to the reference scenario, and data traceability information.
A25: Project emissions EII | B25: Contains data and calculation of greenhouse gas emissions related to the project activity, and data traceability information.
A26: Process diagram | B26: Illustrates the inputs and outputs in both “project” and “reference” scenarios.
A27: Ref. and Proj. Conversion factors | B27: Provides conversion and emission factors that can be adopted in the calculations. Applicants may adopt different values to those proposed, as long as supported with the adequate evidence and (where approriate) a monitoring plan.
A28: Assumptions | B28: Contains all the qualitative and quantitative assumptions adopted by the applicant in support of their submission.
A29: CC credit overview | B29: Overview of the "CC credit calculation" sheet.
A30: CC credit calculation | B30: Contains data and calculation of greenhouse gas emissions related to the carbon capture credit, and data traceability information.
A32: Definitions
A34: Refinputs | B34: Emissions in the reference scenario associated with the use of inputs produced outside the reference system boundary.
A35: Refprocesses | B35: Emissions in the reference scenario associated with processes required to provide the same product(s) that is(are) produced by the project.
A36: RefEoL | B36: Emissions in the reference scenario from End of Life (EoL) of products. Where carbon is incorporated into products, CO2 emissions from eventual carbon release (including by combustion of those products) shall be included in the “end-of-life” box following the rules in methodology section 2.2.9.
A37: Projinputs | B37: Emissions in the project scenario associated with the use of inputs produced outside the project boundary.
A38: Projprocesses | B38: Emissions in the project scenario associated with processes required to provide the product(s).
A39: Projchangeuse | B39: Where a project is associated with savings in use of the product(s), then the change to in-use emissions for the project scenario should be included here (in-use combustion emissions are counted in the combustion box).
A40: ProjEoL | B40: Emissions in the project scenario from End of Life (EoL) of products. Where carbon is incorporated into products, CO2 emissions from eventual carbon release (including through combustion of those products as fuels) shall be included in the “end-of-life” box following the rules in methodology section 2.2.9. If there are other significant changes in expected end of life emissions associated with the project they may also be included here (if there is no expected change in other end of life emissions they need not be considered).
A42: EII Sectors and Products
A44: Sector | B44: Products
A45: Refineries | B45: Fuels (incl. e-fuels, biofuels)
A46: Iron & Steel | B46: Coke
A47: Iron & Steel | B47: Iron
A48: Iron & Steel | B48: Iron ore
A49: Iron & Steel | B49: Steel
A50: Iron & Steel | B50: Cast ferrous metals products
A51: Iron & Steel | B51: Other ferrous metal products or substitute products
...

Sheet Lists
B2: Sectors: | C2: Products in selected sector:
B3: {=_xlfn.UNIQUE('Overview EII'!A45:A95)} -> Refineries | C3: {=Product_list} -> Select sector first
B4: Iron & Steel
B5: Non-ferrous metals
B6: Cement & Lime
B7: Glass, ceramics & construction material
B8: Pulp & paper
B9: Chemicals
B10: Hydrogen
B11: Manufacturing of components for energy intensive industries
B12: Other
B13: Buildings

Sheet Summary
A1: General information
A3: General information | C3: Comment / Instruction | D3: Automated checks
A4: Category | B4: EII | D4: Check that you are using the correct calculator for your project category. See Table 1.1 of the GHG Methodology. --> | E4: =IF(B4="EII", "OK", "ERR") -> OK
A5: Calculator version | B5: v7.0 | C5: Check that you are using the most recent version of the calculator.
A6: Sector | D6: Check that the chosen principal product is consistent with the chosen sector. --> | E6: =IF(ISERROR(MATCH(B7,Product_list,0)), "ERR","OK") -> ERR
A7: Principal product | C7: Select here the principal product that is the main aim of the project. See Section 1.2 of the GHG Methodology.
A8: Function of principal product | C8: - The concept of “function” is added because an innovative product may not be identical to existing ones, but provide the same function. - This line can also be used to specify the principal product, e.g. if 'other' or 'various' is selected above.
A9: Reference product substituted by the principal product, if different | C9: When the principal product performs the same function as a conventional product to which it is not identical please identify the substituted reference product here.
A10: Other products | C10: List here the other products that are not the main aim of the project, and specify their function or the reference product substituted if needed. See Section 1.2 of the Methodology.
A11: Is this a hybrid application? | B11: No | C11: Refer to section 1.2.5 of the GHG Methodology. | D11: Check that if hybrid application is selected there are non-zero emissions for at least one year in one other row on the ''Summary per year' sheet. Otherwise, check that they are zero. --> | E11: {=IF(AND(B11="Yes",MAX(ABS('Summary per year'!B13:L15),ABS('Summary per year'!B20:L22))=0), "ERR", IF(AND(B11="No",MAX(ABS('Summary per year'!B13:L15),ABS('Summary per year'!B20:L22))<>0),"ERR","OK"))} -> OK
A12: For hybrid applications, specify the other relevant project categories (RES, ES, MOB)
A14: Absolute GHG Emissions Avoidance
A15: Net absolute GHG emissions avoided due to operation of the project during the first 10 years of operation, in tCO2e.
A16: Note: The term CCcredit should be zero, unless the project includes a component of carbon capture and storage or utilisation.
A18: Absolute GHG emission avoidance | B18: = | C18: Reference emissions | D18: - | E18: Project emissions | F18: + | G18: CC credit
A19: ∆GHGabs | B19: = | C19: Ref | D19: - | E19: Proj | F19: + | G19: CCcredit
A20: =C20-E20+G20 -> 0 | B20: = | C20: =+ 'Summary per year'!B16 -> 0 | D20: - | E20: =+ 'Summary per year'!B23 -> 0 | F20: + | G20: =+ 'Summary per year'!B25 -> 0
A22: Relative GHG Emissions Avoidance
A23: Relative GHG emissions avoided due to operation of the project during the first 10 years of operation, in percent.
A25: Relative GHG emission avoidance | B25: = | C25: Absolute GHG emission avoidance | D25: ÷ | E25: Reference emissions | G25: Automated checks
A26: ∆GHGrel | B26: = | C26: ∆GHGabs | D26: ÷ | E26: Ref | G26: Check for positive absolute GHG emission avoidance
A27: =IF(A20<=0,0,IF(E27<=0,200%,C27/E27)) -> 0 | B27: = | C27: =A20 -> 0 | D27: ÷ | E27: =C20 -> 0 | G27: =IF(A20<0,"NEGATIVE","OK") -> OK
A29: GHG emissions by scenario and life-cycle step
A30: Reference and project GHG emissions by life-cycle step during the first 10 years of operation, in tCO2e.
A32: Step | B32: Ref | C32: Proj - CCcredit | D32: Avoided emissions
B33: tCO2e | C33: tCO2e | D33: tCO2e
A34: Input | B34: ='Reference emissions EII'!B6 -> 0 | C34: ='Project emissions EII'!B6 -> 0 | D34: =B34-C34 -> 0
A35: Process | B35: ='Reference emissions EII'!B7 -> 0 | C35: ='Project emissions EII'!B7 -> 0 | D35: =B35-C35 -> 0
A36: Change to in-use | C36: ='Project emissions EII'!B8 -> 0 | D36: =B36-C36 -> 0
A37: End-of-life | B37: ='Reference emissions EII'!B8 -> 0 | C37: ='Project emissions EII'!B9 -> 0 | D37: =B37-C37 -> 0
A38: Total EII | B38: =+ SUM(B34:B37) -> 0 | C38: =+ SUM(C34:C37) -> 0 | D38: =B38-C38 -> 0
A39: CC credit | C39: =- G20 -> 0 | D39: =B39-C39 -> 0
A40: Total | B40: =+ SUM(B38:B39) -> 0 | C40: =+ SUM(C38:C39) -> 0 | D40: =B40-C40 -> 0
A42: Additional GHG indicators
A44: Indicators | B44: Description | C44: Reference Scenario | D44: Project Scenario | E44: Data unit | F44: Comment
A45: Quantity of products in the reference and project scenarios | B45: Principal product | C45: =+ 'Reference emissions EII'!Q17 -> 0 | D45: =+'Project emissions EII'!Q17 -> 0 | E45: =IF('Project emissions EII'!F17="","Unit for quantity of principal product [Please state unit of production quantity on sheet 'Project emissions EII']",'Project emissions EII'!F17) -> [Please specify] | F45: The quantity of reference product produced each year must provide an equivalent function to the corresponding product produced in the project scenario.
B46: Product 2 | C46: =+ 'Reference emissions EII'!Q18 -> 0 | D46: =+'Project emissions EII'!Q18 -> 0 | E46: =IF('Project emissions EII'!F18="","Unit for quantity of principal product [Please state unit of production quantity on sheet 'Project emissions EII']",'Project emissions EII'!F18) -> [Please specify] | F46: The quantity of reference product produced each year must provide an equivalent function to the corresponding product produced in the project scenario.
B47: Product 3 | C47: =+ 'Reference emissions EII'!Q19 -> 0 | D47: =+'Project emissions EII'!Q19 -> 0 | E47: =IF('Project emissions EII'!F19="","Unit for quantity of principal product [Please state unit of production quantity on sheet 'Project emissions EII']",'Project emissions EII'!F19) -> [Please specify] | F47: The quantity of reference product produced each year must provide an equivalent function to the corresponding product produced in the project scenario.
A48: Process emissions per unit of product in the reference and project scenarios. Including the credit for carbon capture and storage or utilisation in the project scenario. Refer to the Call Text for the corresponding minimum requirement, where applicable. | B48: Principal product | C48: =IF(C45=0,0,B35/C45) -> 0 | D48: =IF(D45=0,0,SUM(C35,C39)/D45) -> 0 | E48: tCO2e / unit quantity of principal product [Please replace with adequate unit] | F48: In case more than one product is present, adjust the formula as needed so that only the relevant process emissions are included on each line. In case that the production unit is different for the reference and project products (e.g. in case of equivalent function) indicate the relevant unit for each scenario.
B49: Product 2 | E49: tCO2e / unit quantity of product 2 [Please replace with adequate unit]
...

Sheet Summary per year
A1: Summary per year
A2: Estimated values for the reference and project emissions and the absolute GHG emissions avoided during the first 10 year of operation, expressed in tCO2e.
A3: The relative GHG emission avoidance is expressed in percent.
A5: Non-hybrid projects shall only report values for the relevant category.
A6: Hybrid projects should include in the calculator the sheet "Project emissions" and "Reference emissions" for each of the relevant categories, and report emissions in the table below by providing links as appropriate.
A8: Note: Make sure that all the checks in column "N" are marked 'OK', when preparing your calculations.
A9: Note: Make sure that also the checks in sheets "Project emissions", "Reference emissions", and "CC credit_calculation" are marked 'OK'.
A11: Reference emissions | B11: TOT | C11: Year 1 | D11: Year 2 | E11: Year 3 | F11: Year 4 | G11: Year 5 | H11: Year 6 | I11: Year 7 | J11: Year 8 | K11: Year 9 | L11: Year 10 | M11: Automated checks
A12: Refy, EII | B12: =SUM(C12:L12) -> 0 | C12: ='Reference emissions EII'!T21 -> 0 | D12: ='Reference emissions EII'!U21 -> 0 | E12: ='Reference emissions EII'!V21 -> 0 | F12: ='Reference emissions EII'!W21 -> 0 | G12: ='Reference emissions EII'!X21 -> 0 | H12: ='Reference emissions EII'!Y21 -> 0 | I12: ='Reference emissions EII'!Z21 -> 0 | J12: ='Reference emissions EII'!AA21 -> 0 | ... L12: ='Reference emissions EII'!AC21 -> 0
A13: Refy, RES | B13: =SUM(C13:L13) -> 0
A14: Refy, ES | B14: =SUM(C14:L14) -> 0
A15: Refy, MOB | B15: =SUM(C15:L15) -> 0
A16: Refy, TOT | B16: =SUM(C16:L16) -> 0 | C16: =+ SUM(C12:C15) -> 0 | D16: =+ SUM(D12:D15) -> 0 | E16: =+ SUM(E12:E15) -> 0 | F16: =+ SUM(F12:F15) -> 0 | G16: =+ SUM(G12:G15) -> 0 | H16: =+ SUM(H12:H15) -> 0 | I16: =+ SUM(I12:I15) -> 0 | J16: =+ SUM(J12:J15) -> 0 | ... L16: =+ SUM(L12:L15) -> 0 | M16: Check that the vertical sum corresponds to the horizontal sum. --> | N16: =+ IF(ROUND(B16,2)=ROUND(SUM(B12:B15),2),"OK","ERR") -> OK
A18: Project emissions | B18: TOT | C18: Year 1 | D18: Year 2 | E18: Year 3 | F18: Year 4 | G18: Year 5 | H18: Year 6 | I18: Year 7 | J18: Year 8 | K18: Year 9 | L18: Year 10 | M18: Automated checks
A19: Projy, EII | B19: =SUM(C19:L19) -> 0 | C19: ='Project emissions EII'!T21 -> 0 | D19: ='Project emissions EII'!U21 -> 0 | E19: ='Project emissions EII'!V21 -> 0 | F19: ='Project emissions EII'!W21 -> 0 | G19: ='Project emissions EII'!X21 -> 0 | H19: ='Project emissions EII'!Y21 -> 0 | I19: ='Project emissions EII'!Z21 -> 0 | J19: ='Project emissions EII'!AA21 -> 0 | ... L19: ='Project emissions EII'!AC21 -> 0
A20: Projy, RES | B20: =SUM(C20:L20) -> 0
A21: Projy, ES | B21: =SUM(C21:L21) -> 0
A22: Projy, MOB | B22: =SUM(C22:L22) -> 0
A23: Projy, TOT | B23: =SUM(C23:L23) -> 0 | C23: =+ SUM(C19:C22) -> 0 | D23: =+ SUM(D19:D22) -> 0 | E23: =+ SUM(E19:E22) -> 0 | F23: =+ SUM(F19:F22) -> 0 | G23: =+ SUM(G19:G22) -> 0 | H23: =+ SUM(H19:H22) -> 0 | I23: =+ SUM(I19:I22) -> 0 | J23: =+ SUM(J19:J22) -> 0 | ... L23: =+ SUM(L19:L22) -> 0 | M23: Check that the vertical sum corresponds to the horizontal sum. --> | N23: =+ IF(ROUND(B23,2)=ROUND(SUM(B19:B22),2),"OK","ERR") -> OK
A25: CCcredit, y | B25: =SUM(C25:L25) -> 0 | C25: =+ 'CC credit calculation'!R21 -> 0 | D25: =+ 'CC credit calculation'!S21 -> 0 | E25: =+ 'CC credit calculation'!T21 -> 0 | F25: =+ 'CC credit calculation'!U21 -> 0 | G25: =+ 'CC credit calculation'!V21 -> 0 | H25: =+ 'CC credit calculation'!W21 -> 0 | I25: =+ 'CC credit calculation'!X21 -> 0 | J25: =+ 'CC credit calculation'!Y21 -> 0 | ... L25: =+ 'CC credit calculation'!AA21 -> 0
A26: Note: The term CCcredit should be zero, unless the project includes a component of carbon capture and storage or utilisation.
A28: GHG emission avoidance | B28: TOT | C28: Year 1 | D28: Year 2 | E28: Year 3 | F28: Year 4 | G28: Year 5 | H28: Year 6 | I28: Year 7 | J28: Year 8 | K28: Year 9 | L28: Year 10 | M28: Automated checks
A29: ∆GHGabs | B29: =SUM(C29:L29) -> 0 | C29: =+ C16 - C23 + C25 -> 0 | D29: =+ D16 - D23 + D25 -> 0 | E29: =+ E16 - E23 + E25 -> 0 | F29: =+ F16 - F23 + F25 -> 0 | G29: =+ G16 - G23 + G25 -> 0 | H29: =+ H16 - H23 + H25 -> 0 | I29: =+ I16 - I23 + I25 -> 0 | J29: =+ J16 - J23 + J25 -> 0 | ... L29: =+ L16 - L23 + L25 -> 0 | M29: Check that the value is consistent between the "Summary" and the "Summary per year" sheets. --> | N29: =+ IF(ROUND(B29,2)=ROUND(Summary!A20,2),"OK","ERR") -> OK
A30: ∆GHGrel | B30: =IF(B29<=0,0, IF(B16<=0, 100%, B29/B16)) -> 0 | C30: =IF(C29<=0,0, IF(C16<=0, 100%, C29/C16)) -> 0 | D30: =IF(D29<=0,0, IF(D16<=0, 100%, D29/D16)) -> 0 | E30: =IF(E29<=0,0, IF(E16<=0, 100%, E29/E16)) -> 0 | F30: =IF(F29<=0,0, IF(F16<=0, 100%, F29/F16)) -> 0 | G30: =IF(G29<=0,0, IF(G16<=0, 100%, G29/G16)) -> 0 | H30: =IF(H29<=0,0, IF(H16<=0, 100%, H29/H16)) -> 0 | I30: =IF(I29<=0,0, IF(I16<=0, 100%, I29/I16)) -> 0 | ... L30: =IF(L29<=0,0, IF(L16<=0, 100%, L29/L16)) -> 0 | M30: Check that the value is consistent between the "Summary" and the "Summary per year" sheets. --> | N30: =+ IF(ROUND(B30,2)=ROUND(Summary!A27,2),"OK","ERR") -> OK

Sheet Process Diagram
B2: Please insert:
B3: The applicants shall provide in the GHG calculator a detailed process diagram for the project and reference scenarios, indicating all the sub-processes, inputs, and products for both scenarios. The diagram shall clearly indicate the system boundary and should include quantities of material and energy flows where relevant. The applicants should develop the process diagram to adequately represent the complexity of their project. See Methodology section 2.2.4.

Sheet Reference emissions EII
A1: Reference emissions summary
A2: This summary table uses the sumif function to add emissions from rows with each label. This requires the row labels below to exactly match the row labels used here.
A3: If adding, removing or moving rows applicants should check that the total emissions for each label are still correctly summed.
A5: Row Labels | B5: Sum of tCO2e | C5: Automated checks
A6: Refinputs | B6: =SUMIF($A$20:$A$34,A6,$AD$20:$AD$34) -> 0
A7: Refprocesses | B7: =SUMIF($A$20:$A$34,A7,$AD$20:$AD$34) -> 0
A8: RefEoL | B8: =SUMIF($A$20:$A$34,A8,$AD$20:$AD$34) -> 0
A9: Grand Total | B9: =SUM(B6:B8) -> 0 | C9: Check that the horizontal and vertical sums are consistent | D9: =+ IF(AND(ROUND(B9,2)=ROUND(AD21,2),ROUND(B9,2)=ROUND(SUM(T21:AC21),2)),"OK","ERR") -> OK
A11: Reference emissions calculation
A12: Note: for many projects the reference emissions for processes will be based on an EU ETS benchmark, fossil fuel comparator or other natural-gas-based fossil fuel default (e.g. methane, methanol). In these cases there is no need to further disaggregate process emissions, and often there will be no emissions in the inputs or end of life boxes. Note though that there may still be input emissions to include in the case where the reference is based on an EU ETS benchmark.
A14: Operational data | AF14: Data traceability
A15: Emission Source | B15: Plant / Unit | C15: Process | D15: Parameter | E15: Description of parameter | F15: Unit of measure | G15: Year 1 | H15: Year 2 | I15: Year 3 | J15: Year 4 | K15: Year 5 | L15: Year 6 | M15: Year 7 | N15: Year 8 | O15: Year 9 | P15: Year 10 | Q15: Total | R15: Comments about operational data | S15: t CO2e / [unit] | T15: Year 1 (t CO2e) | U15: Year 2 (t CO2e) | V15: Year 3 (t CO2e) | W15: Year 4 (t CO2e) | X15: Year 5 (t CO2e) | Y15: Year 6 (t CO2e) | Z15: Year 7 (t CO2e) | AA15: Year 8 (t CO2e) | AB15: Year 9 (t CO2e) | AC15: Year 10 (t CO2e) | AD15: t CO2e | AE15: Comments about GHG emissions | AF15: Parameter to be monitored / not monitored | AG15: Data source for monitoring | AH15: Reliability | AI15: Monitoring frequency | AJ15: Department responsible for collection and archiving | AK15: Monitoring approach and equipment used, including details on accuracy and calibration | AL15: QA/QC Procedures | AM15: Additional description of the monitoring system
A16: Quantity of reference products produced per year
D17: Quantity of Reference Product 1 (replaced by the principal product) | E17: [Please specify] | F17: [Please specify] | Q17: =SUM(G17:P17) -> 0 | R17: The quantity of reference product produced each year must provide an equivalent function to the corresponding product produced in the project scenario.
D18: Quantity of Reference Product 2 | E18: [Please specify] | F18: [Please specify] | Q18: =SUM(G18:P18) -> 0 | R18: The quantity of reference product produced each year must provide an equivalent function to the corresponding product produced in the project scenario.
D19: Quantity of Reference Product 3 | E19: [Please specify] | F19: [Please specify] | Q19: =SUM(G19:P19) -> 0 | R19: The quantity of reference product produced each year must provide an equivalent function to the corresponding product produced in the project scenario.
A20: Total reference emissions per year
A21: Refyear | T21: =SUM(T22:T34) -> 0 | U21: =SUM(U22:U34) -> 0 | V21: =SUM(V22:V34) -> 0 | W21: =SUM(W22:W34) -> 0 | X21: =SUM(X22:X34) -> 0 | Y21: =SUM(Y22:Y34) -> 0 | Z21: =SUM(Z22:Z34) -> 0 | AA21: =SUM(AA22:AA34) -> 0 | ... AD21: =SUM(AD22:AD34) -> 0 | AE21: Please verify that the horizontal sum per year and the vertical sum per contribution yield the same result as the grand total in the pivot table
A22: Inputs [add rows needed]
A23: Refinputs | F23: [Please specify] | Q23: =SUM(G23:P23) -> 0 | AD23: =SUM(T23:AC23) -> 0 | AE23: [Link to the appropriate conversion factors from tab "Ref Conversion Factors"]
A24: Refinputs | F24: [Please specify] | Q24: =SUM(G24:P24) -> 0 | AD24: =SUM(T24:AC24) -> 0 | AE24: [Link to the appropriate conversion factors from tab "Ref Conversion Factors"]
A25: Refinputs | F25: [Please specify] | Q25: =SUM(G25:P25) -> 0 | AD25: =SUM(T25:AC25) -> 0 | AE25: [Link to the appropriate conversion factors from tab "Ref Conversion Factors"]
A26: Processes [add rows as needed]
A27: Refprocesses | F27: [Please specify] | Q27: =SUM(G27:P27) -> 0 | AD27: =SUM(T27:AC27) -> 0 | AE27: [Link to the appropriate conversion factors from tab "Ref Conversion Factors"]
A28: Refprocesses | F28: [Please specify] | Q28: =SUM(G28:P28) -> 0 | AD28: =SUM(T28:AC28) -> 0 | AE28: [Link to the appropriate conversion factors from tab "Ref Conversion Factors"]
A29: Refprocesses | F29: [Please specify] | Q29: =SUM(G29:P29) -> 0 | AD29: =SUM(T29:AC29) -> 0 | AE29: [Link to the appropriate conversion factors from tab "Ref Conversion Factors"]
A30: End-Of-Life [add rows as needed]
A31: RefEoL | F31: [Please specify] | Q31: =SUM(G31:P31) -> 0 | AD31: =SUM(T31:AC31) -> 0 | AE31: [Link to the appropriate conversion factors from tab "Ref Conversion Factors"]
A32: RefEoL | F32: [Please specify] | Q32: =SUM(G32:P32) -> 0 | AD32: =SUM(T32:AC32) -> 0 | AE32: [Link to the appropriate conversion factors from tab "Ref Conversion Factors"]
A33: RefEoL | F33: [Please specify] | Q33: =SUM(G33:P33) -> 0 | AD33: =SUM(T33:AC33) -> 0 | AE33: [Link to the appropriate conversion factors from tab "Ref Conversion Factors"]
A34: Multipliers for projects manufacturing electrolysers and their components [add rows as needed]
A35: Multiplier | D35: N | E35: Number of components produced and supplied to the market for each year of operation of the project. | F35: Number of components | Q35: =SUM(G35:P35) -> 0
A36: Multiplier | D36: UP | E36: Applicable use period of the manufactured innovative component. | F36: years of use of the component | G36: 5 | H36: 5 | I36: 5 | J36: 5 | K36: 5 | L36: 5 | M36: 5 | N36: 5 | O36: 5 | P36: 5 | R36: Please reduce if the lifetime of the component is shorter than 5 years.
A37: Multiplier | D37: CScomponent | E37: Cost share of the innovative component as a fraction of the total capital cost of the relevant facility or retail price of the consumer product, | F37: %

Sheet Project emissions EII
A1: Project emissions summary
A2: This summary table uses the sumif function to add emissions from rows with each label. This requires the row labels below to exactly match the row labels used here.
A3: If adding, removing or moving rows applicants should check that the total emissions for each label are still correctly summed.
A5: Row Labels | B5: Sum of tCO2e | C5: Automated checks
A6: Projinputs | B6: =SUMIF($A$20:$A$38,A6,$AD$20:$AD$38) -> 0
A7: Projprocesses | B7: =SUMIF($A$20:$A$38,A7,$AD$20:$AD$38) -> 0
A8: Projchangeuse | B8: =SUMIF($A$20:$A$38,A8,$AD$20:$AD$38) -> 0
A9: ProjEoL | B9: =SUMIF($A$20:$A$38,A9,$AD$20:$AD$38) -> 0
A10: Grand Total | B10: =SUM(B6:B9) -> 0 | C10: Check that the horizontal and vertical sums are consistent | D10: =+ IF(AND(ROUND(B10,2)=ROUND(AD21,2),ROUND(B10,2)=ROUND(SUM(T21:AC21),2)),"OK","ERR") -> OK
A12: Project emissions calculation
A14: Operational data | R14: GHG emissions in the project scenario | AF14: Data traceability
A15: Emission source | B15: Plant / Unit | C15: Process | D15: Parameter | E15: Description of parameter | F15: Unit of measure | G15: Year 1 | H15: Year 2 | I15: Year 3 | J15: Year 4 | K15: Year 5 | L15: Year 6 | M15: Year 7 | N15: Year 8 | O15: Year 9 | P15: Year 10 | Q15: Total | R15: Comments about operational data | S15: t CO2e / [unit] | T15: Year 1 (t CO2e) | U15: Year 2 (t CO2e) | V15: Year 3 (t CO2e) | W15: Year 4 (t CO2e) | X15: Year 5 (t CO2e) | Y15: Year 6 (t CO2e) | Z15: Year 7 (t CO2e) | AA15: Year 8 (t CO2e) | AB15: Year 9 (t CO2e) | AC15: Year 10 (t CO2e) | AD15: t CO2e | AE15: Comments about GHG emissions | AF15: Parameter to be monitored / not monitored | AG15: Data source for monitoring | AH15: Reliability | AI15: Monitoring frequency | AJ15: Department responsible for collection and archiving | AK15: Monitoring approach and equipment used, including details on accuracy and calibration | AL15: QA/QC Procedures | AM15: Additional description of the monitoring system
A16: Quantity of product produced per year
D17: Quantity of Principal Product | E17: [Please specify] | F17: [Please specify] | Q17: =SUM(G17:P17) -> 0 | R17: The quantity of each product produced in the project scenario must provide an equivalent function to the corresponding reference product produced in the reference scenario.
D18: Quantity of Product 2 | E18: [Please specify] | F18: [Please specify] | Q18: =SUM(G18:P18) -> 0 | R18: The quantity of each product produced in the project scenario must provide an equivalent function to the corresponding reference product produced in the reference scenario.
D19: Quantity of Product 3 | E19: [Please specify] | F19: [Please specify] | Q19: =SUM(G19:P19) -> 0 | R19: The quantity of each product produced in the project scenario must provide an equivalent function to the corresponding reference product produced in the reference scenario.
A20: Total project emissions per year
A21: Projyear | T21: =SUM(T22:T38) -> 0 | U21: =SUM(U22:U38) -> 0 | V21: =SUM(V22:V38) -> 0 | W21: =SUM(W22:W38) -> 0 | X21: =SUM(X22:X38) -> 0 | Y21: =SUM(Y22:Y38) -> 0 | Z21: =SUM(Z22:Z38) -> 0 | AA21: =SUM(AA22:AA38) -> 0 | ... AD21: =SUM(AD22:AD38) -> 0 | AE21: Please verify that the horizontal sum per year and the vertical sum per contribution yield the same result as the grand total in the pivot table (noting that for component manufacturing projects the vertical sum needs to be adjusted for cost share when making this check)
A22: Inputs [add rows as needed]
A23: Projinputs | F23: [Please specify] | Q23: =SUM(G23:P23) -> 0 | AD23: =SUM(T23:AC23) -> 0 | AE23: [Link to the appropriate conversion factor from tab "Proj Conversion Factors"]
A24: Projinputs | F24: [Please specify] | Q24: =SUM(G24:P24) -> 0 | AD24: =SUM(T24:AC24) -> 0 | AE24: [Link to the appropriate conversion factor from tab "Proj Conversion Factors"]
A25: Projinputs | F25: [Please specify] | Q25: =SUM(G25:P25) -> 0 | AD25: =SUM(T25:AC25) -> 0 | AE25: [Link to the appropriate conversion factor from tab "Proj Conversion Factors"]
A26: Processes [add rows as needed]
A27: Projprocesses | F27: [Please specify] | Q27: =SUM(G27:P27) -> 0 | AD27: =SUM(T27:AC27) -> 0 | AE27: [Link to the appropriate conversion factor from tab "Proj Conversion Factors"]
A28: Projprocesses | F28: [Please specify] | Q28: =SUM(G28:P28) -> 0 | AD28: =SUM(T28:AC28) -> 0 | AE28: [Link to the appropriate conversion factor from tab "Proj Conversion Factors"]
A29: Projprocesses | F29: [Please specify] | Q29: =SUM(G29:P29) -> 0 | AD29: =SUM(T29:AC29) -> 0 | AE29: [Link to the appropriate conversion factor from tab "Proj Conversion Factors"]
A30: Change to in-use [add rows as needed]
A31: Projchangeuse | F31: [Please specify] | Q31: =SUM(G31:P31) -> 0 | AD31: =SUM(T31:AC31) -> 0 | AE31: [Link to the appropriate conversion factor from tab "Proj Conversion Factors"]
A32: Projchangeuse | F32: [Please specify] | Q32: =SUM(G32:P32) -> 0 | AD32: =SUM(T32:AC32) -> 0 | AE32: [Link to the appropriate conversion factor from tab "Proj Conversion Factors"]
A33: Projchangeuse | F33: [Please specify] | Q33: =SUM(G33:P33) -> 0 | AD33: =SUM(T33:AC33) -> 0 | AE33: [Link to the appropriate conversion factor from tab "Proj Conversion Factors"]
A34: End-Of-Life [add rows as needed]
A35: ProjEoL | F35: [Please specify] | Q35: =SUM(G35:P35) -> 0 | AD35: =SUM(T35:AC35) -> 0 | AE35: [Link to the appropriate conversion factor from tab "Proj Conversion Factors"]
A36: ProjEoL | F36: [Please specify] | Q36: =SUM(G36:P36) -> 0 | AD36: =SUM(T36:AC36) -> 0 | AE36: [Link to the appropriate conversion factor from tab "Proj Conversion Factors"]
A37: ProjEoL | F37: [Please specify] | Q37: =SUM(G37:P37) -> 0 | AD37: =SUM(T37:AC37) -> 0 | AE37: [Link to the appropriate conversion factor from tab "Proj Conversion Factors"]
A38: Multipliers for projects manufacturing electrolysers and their components [add rows as needed]
A39: Multiplier | D39: N | E39: Number of components produced and supplied to the market for each year of operation of the project. | F39: Number of components | G39: ='Reference emissions EII'!G35 -> 0 | H39: ='Reference emissions EII'!H35 -> 0 | I39: ='Reference emissions EII'!I35 -> 0 | J39: ='Reference emissions EII'!J35 -> 0 | K39: ='Reference emissions EII'!K35 -> 0 | L39: ='Reference emissions EII'!L35 -> 0 | M39: ='Reference emissions EII'!M35 -> 0 | N39: ='Reference emissions EII'!N35 -> 0 | ... P39: ='Reference emissions EII'!P35 -> 0 | Q39: =SUM(G39:P39) -> 0 | R39: Same as in the reference scenario | AM39: Same as in the reference scenario
A40: Multiplier | D40: UP | E40: Applicable use period of the manufactured innovative component. | F40: years of use of the component | G40: ='Reference emissions EII'!G36 -> 5 | H40: ='Reference emissions EII'!H36 -> 5 | I40: ='Reference emissions EII'!I36 -> 5 | J40: ='Reference emissions EII'!J36 -> 5 | K40: ='Reference emissions EII'!K36 -> 5 | L40: ='Reference emissions EII'!L36 -> 5 | M40: ='Reference emissions EII'!M36 -> 5 | N40: ='Reference emissions EII'!N36 -> 5 | ... P40: ='Reference emissions EII'!P36 -> 5 | R40: Same as in the reference scenario | AM40: Same as in the reference scenario
A41: Multiplier | D41: CScomponent | E41: Cost share of the innovative component as a fraction of the total capital cost of the relevant facility or retail price of the consumer product, | F41: % | G41: ='Reference emissions EII'!G37 -> 0 | H41: ='Reference emissions EII'!H37 -> 0 | I41: ='Reference emissions EII'!I37 -> 0 | J41: ='Reference emissions EII'!J37 -> 0 | K41: ='Reference emissions EII'!K37 -> 0 | L41: ='Reference emissions EII'!L37 -> 0 | M41: ='Reference emissions EII'!M37 -> 0 | N41: ='Reference emissions EII'!N37 -> 0 | ... P41: ='Reference emissions EII'!P37 -> 0 | R41: Same as in the reference scenario | AM41: Same as in the reference scenario

Sheet Ref Conversion Factors EII
A1: Default factors for EII reference emissions
A2: Type of data | B2: Description | C2: Fuel / Feedstock / Product | D2: Value | E2: Data unit | F2: Source of data | G2: Comment | H2: Data traceability
H3: Parameter to be monitored / not monitored | I3: Data source for monitoring | J3: Reliability | K3: Monitoring frequency | L3: Department responsible for collection and archiving | M3: Monitoring approach and equipment used, including details on accuracy and calibration | N3: QA/QC Procedures | O3: Additional description of the monitoring system
A4: ETS Product benchmarks | B4: Coke-oven coke (obtained from the carbonisation of coking coal, at high temperature) or gas-works coke (by-product of gas-works plants) expressed as tons of dry coke. Lignite coke is not covered by this benchmark | C4: Coke | D4: 0.217 | E4: tCO2e / t | F4: Commission Implementing Regulation (EU) 2021/447 of 12 March 2021 determining revised benchmark values for free allocation of emission allowances for the period from 2021 to 2025 pursuant to Article 10a(2) of Directive 2003/87/EC of the European Parliament and of the Council. | G4: All processes directly or indirectly linked to the process units coke ovens, H2S/NH3 incineration, coal preheating (defreezing), coke gas extractor, desulphurisation unit, distillation unit, steam generation plant, pressure control in batteries, biological water treatment, miscellaneous heating of by-products and hydrogen separator are included. Coke oven gas cleaning is included
A5: ETS Product benchmarks | B5: Agglomerated iron-bearing product containing iron ore fines, fluxes and ironcontaining recycling materials with the chemical and physical properties such as the level of basicity, mechanical strength and permeability required to deliver iron and necessary flux materials into iron ore reduction processes | C5: Sintered ore | D5: 0.157 | E5: tCO2e / t | F5: Commission Implementing Regulation (EU) 2021/447 of 12 March 2021 determining revised benchmark values for free allocation of emission allowances for the period from 2021 to 2025 pursuant to Article 10a(2) of Directive 2003/87/EC of the European Parliament and of the Council. | G5: All processes directly or indirectly linked to the process units sinter strand, ignition, feedstock preparation units, hot screening unit, sinter cooling unit, cold screening unit and steam generation unit are included
A6: ETS Product benchmarks | B6: Liquid iron saturated with carbon for further processing | C6: Hot metal | D6: 1.288 | E6: tCO2e / t | F6: Commission Implementing Regulation (EU) 2021/447 of 12 March 2021 determining revised benchmark values for free allocation of emission allowances for the period from 2021 to 2025 pursuant to Article 10a(2) of Directive 2003/87/EC of the European Parliament and of the Council. | G6: All processes directly or indirectly linked to the process units blast furnace, hot metal treatment units, blast furnace blowers, blast furnace hot stoves, basic oxygen furnace, secondary metallurgy units, vacuum ladles, casting units (including cutting), slag treatment unit, burden preparation, BF gas treatment unit, dedusting units, scrap pre-heating, coal drying for PCI, vessels preheating stands, casting ingots preheating stands, compressed air production, dust treatment unit (briquetting), sludge treatment unit (briquetting), steam injection in BF unit, steam generation plant, converter BOF gas cooling and miscellaneous are included
A7: ETS Product benchmarks | B7: Anodes for aluminium electrolysis use consisting of petrol coke, pitch and normally recycled anodes, which are formed to shape specifically intended for a particular smelter and baked in anode baking ovens to a temperature of around 1 150 °C | C7: Pre-bake anode | D7: 0.312 | E7: tCO2e / t | F7: Commission Implementing Regulation (EU) 2021/447 of 12 March 2021 determining revised benchmark values for free allocation of emission allowances for the period from 2021 to 2025 pursuant to Article 10a(2) of Directive 2003/87/EC of the European Parliament and of the Council. | G7: All processes directly or indirectly linked to the production of pre-bake anodes are included
A8: ETS Product benchmarks | B8: Unwrought non-alloy liquid aluminium from electrolysis | C8: Aluminium | D8: 1.464 | E8: tCO2e / t | F8: Commission Implementing Regulation (EU) 2021/447 of 12 March 2021 determining revised benchmark values for free allocation of emission allowances for the period from 2021 to 2025 pursuant to Article 10a(2) of Directive 2003/87/EC of the European Parliament and of the Council. | G8: All processes directly or indirectly linked to the production step electrolysis are included
A9: ETS Product benchmarks | B9: Grey cement clinker as total clinker produced | C9: Grey cement clinker | D9: 0.693 | E9: tCO2e / t | F9: Commission Implementing Regulation (EU) 2021/447 of 12 March 2021 determining revised benchmark values for free allocation of emission allowances for the period from 2021 to 2025 pursuant to Article 10a(2) of Directive 2003/87/EC of the European Parliament and of the Council. | G9: All processes directly or indirectly linked to the production of grey cement clinker are included
A10: ETS Product benchmarks | B10: White cement clinker for use as main binding component in the formulation of materials such as joint filers, ceramic tile adhesives, insulation, and anchorage mortars, industrial floor mortars, ready mixed plaster, repair mortars, and water-tight coatings with maximum average contents of 0,4 mass-% Fe2O3, 0,003 mass-% Cr2O3 and 0,03 mass-% Mn2O3 | C10: White cement clinker | D10: 0.957 | E10: tCO2e / t | F10: Commission Implementing Regulation (EU) 2021/447 of 12 March 2021 determining revised benchmark values for free allocation of emission allowances for the period from 2021 to 2025 pursuant to Article 10a(2) of Directive 2003/87/EC of the European Parliament and of the Council. | G10: All processes directly or indirectly linked to the production of white cement clinker are included
A11: ETS Product benchmarks | B11: Quicklime: calcium oxide (CaO) produced by the decarbonation of limestone (CaCO3) as ‘standard pure’ lime with a free CaO content of 94,5 %. Lime produced and consumed in the same installation for purification processes is not covered by this product benchmark | C11: Lime | D11: 0.725 | E11: tCO2e / t | F11: Commission Implementing Regulation (EU) 2021/447 of 12 March 2021 determining revised benchmark values for free allocation of emission allowances for the period from 2021 to 2025 pursuant to Article 10a(2) of Directive 2003/87/EC of the European Parliament and of the Council. | G11: All processes directly or indirectly linked to the production of lime are included
A12: ETS Product benchmarks | B12: Dolime or calcined dolomite as mixture of calcium and magnesium oxides produced by the decarbonation of dolomite (CaCO3.MgCO3) with a residual CO2 exceeding 0,25 %, a free MgO content between 25 % and 40 % and a bulk density of the commercial product below 3,05 g/cm3. Dolime shall be expressed as ‘standard pure dolime’ quality with a free CaO content of 57,4 % and a free MgO content of 38,0 % | C12: Dolime | D12: 0.815 | E12: tCO2e / t | F12: Commission Implementing Regulation (EU) 2021/447 of 12 March 2021 determining revised benchmark values for free allocation of emission allowances for the period from 2021 to 2025 pursuant to Article 10a(2) of Directive 2003/87/EC of the European Parliament and of the Council. | G12: All processes directly or indirectly linked to the production of dolime are included
A13: ETS Product benchmarks | B13: Mixture of calcium and magnesium oxides used solely for the production of refractory bricks and other refractory products with a minimum bulk density of 3,05 g/cm3 | C13: Sintered dolime | D13: 1.406 | E13: tCO2e / t | F13: Commission Implementing Regulation (EU) 2021/447 of 12 March 2021 determining revised benchmark values for free allocation of emission allowances for the period from 2021 to 2025 pursuant to Article 10a(2) of Directive 2003/87/EC of the European Parliament and of the Council. | G13: All processes directly or indirectly linked to the production of sintered dolime are included
A14: ETS Product benchmarks | B14: Float/ground/polish glass (as tons of glass exiting the lehr) | C14: Float glass | D14: 0.399 | E14: tCO2e / t | F14: Commission Implementing Regulation (EU) 2021/447 of 12 March 2021 determining revised benchmark values for free allocation of emission allowances for the period from 2021 to 2025 pursuant to Article 10a(2) of Directive 2003/87/EC of the European Parliament and of the Council. | G14: All processes directly or indirectly linked to the production steps melter, refiner, working end, bath and lehr are included
A15: ETS Product benchmarks | B15: Bottles of colourless glass of a nominal capacity < 2,5 litres, for beverages and foodstuffs (excluding bottles covered with leather or composition leather; infant’s feeding bottles) except extra-white flint products with an iron oxide content expressed as percent Fe2O3 by weight lower than 0,03 % and colour coordinates of L in the range 100 to 87, of a in the range 0 to – 5 and of b in the range 0 to 3 (using the CIELAB advocated by the Commission internationale d’éclairage) expressed as tons of packed product | C15: Bottles and jars of colourless glass | D15: 0.29 | E15: tCO2e / t | F15: Commission Implementing Regulation (EU) 2021/447 of 12 March 2021 determining revised benchmark values for free allocation of emission allowances for the period from 2021 to 2025 pursuant to Article 10a(2) of Directive 2003/87/EC of the European Parliament and of the Council. | G15: All processes directly or indirectly linked to the production steps materials handling, melting, forming, downstream processing, packaging and ancillary processes are included
... A55: ETS Product benchmarks | B55: The ethylene oxide/ethylene glycol benchmark covers the products ethylene oxide (EO, high purity), monoethylene glycol (MEG, standard grade + fibre grade (high purity)), diethylene glycol (DEG), triethylene glycol (TEG). The total amount of products is expressed in terms of EOequivalents (EOE), which are defined as the amount of EO (in mass) that is embedded in one mass unit of the specific glycol | C55: Ethylene oxide/ ethylene glycols | D55: 0.389 | E55: tCO2e / t | F55: Commission Implementing Regulation (EU) 2021/447 of 12 March 2021 determining revised benchmark values for free allocation of emission allowances for the period from 2021 to 2025 pursuant to Article 10a(2) of Directive 2003/87/EC of the European Parliament and of the Council. | G55: All processes directly or indirectly linked to the process units EO production, EO purification and glycol section are included. The total electricity consumption (and the related indirect emissions) within the system boundaries is covered by this product benchmark
A56: ETS Product benchmarks | B56: [not specified] | C56: Heat | D56: 47.3 | E56: tCO2e / TJ | F56: Commission Implementing Regulation (EU) 2021/447 of 12 March 2021 determining revised benchmark values for free allocation of emission allowances for the period from 2021 to 2025 pursuant to Article 10a(2) of Directive 2003/87/EC of the European Parliament and of the Council.
A57: GHG emission factor | B57: Net amount of electricity exported from the project, refer to section 1.4.3.1 of the GHG Methodology. | C57: Electricity | D57: 0.176 | E57: tCO2e / MWh | F57: EUCO3232.5 scenario on Member States | G57: Base year 2030. Combustion only. EU average mix
A58: GHG emission factor | B58: Net amount of electricity exported from the project, refer to section 1.4.3.1 of the GHG Methodology. | C58: Electricity | D58: 48.8 | E58: tCO2e / TJ | F58: EUCO3232.5 scenario on Member States | G58: Base year 2030. Combustion only. EU average mix
A59: Natural-gas-based fossil default | B59: Combustion | C59: Natural gas | D59: 0.202 | E59: tCO2 / MWh | F59: COMMISSION DELEGATED REGULATION (EU) 2018/2066 of 19 December 2018, annex VI | G59: 56.2 tCO2/TJ times 0.0036 TJ/MWh.
A60: Natural-gas-based fossil default | B60: Combustion | C60: Natural gas | D60: 56.2 | E60: tCO2e / TJ | F60: COMMISSION DELEGATED REGULATION (EU) 2018/2066 of 19 December 2018, annex VI
A61: Natural-gas-based fossil default | C61: Methanol | D61: 97.1 | E61: tCO2e / TJ | F61: IF GHG emission methodology
A62: Fossil fuel comparator | C62: Diesel | D62: 80.4 | E62: tCO2e / TJ | F62: IF GHG emission methodology | G62: Substituted fossil transport fuel
A63: Fossil fuel comparator | C63: Gasoline | D63: 78.9 | E63: tCO2e / TJ | F63: IF GHG emission methodology | G63: Substituted fossil transport fuel
A64: Fossil fuel comparator | C64: LPG | D64: 65.4 | E64: tCO2e / TJ | F64: IF GHG emission methodology | G64: Substituted fossil transport fuel
A65: Fossil fuel comparator | C65: Aviation kerosene | D65: 78.3 | E65: tCO2e / TJ | F65: IF GHG emission methodology | G65: Substituted fossil transport fuel
A66: Fossil fuel comparator | C66: Aviation gasoline | D66: 78.9 | E66: tCO2e / TJ | F66: IF GHG emission methodology | G66: Substituted fossil transport fuel
A67: Fossil fuel comparator | C67: Marine fuel (including gas oil and fuel oil) | D67: 78 | E67: tCO2e / TJ | F67: IF GHG emission methodology | G67: Substituted fossil transport fuel
A68: Fossil fuel comparator | C68: Synthetic crude | D68: 75.5 | E68: tCO2e / TJ | F68: IF GHG emission methodology | G68: Substituted fossil transport fuel
A70: Alternative factors
A71: Type of data | B71: Description | C71: Fuel / Feedstock / Product | D71: Value | E71: Data unit | F71: Source of data | G71: Comment | H71: Data traceability
H72: Parameter to be monitored / not monitored | I72: Data source for monitoring | J72: Reliability | K72: Monitoring frequency | L72: Department responsible for collection and archiving | M72: Monitoring approach and equipment used, including details on accuracy and calibration | N72: QA/QC Procedures | O72: Additional description of the monitoring system

Sheet Proj Conversion Factors EII
A1: Default factors for EII project emissions
A2: Type of data | B2: Description | C2: Fuel / Feedstock / Product | D2: Value | E2: Data unit | F2: Source of data | G2: Comment | H2: Data traceability
H3: Parameter to be monitored / not monitored | I3: Data source for monitoring | J3: Reliability | K3: Monitoring frequency | L3: Department responsible for collection and archiving | M3: Monitoring approach and equipment used, including details on accuracy and calibration | N3: QA/QC Procedures | O3: Additional description of the monitoring system
A4: GHG emission factor | B4: Electricity as input | C4: Electricity | D4: 0 | E4: tCO2e/TJ | F4: EUCO3232.5 scenario on Member States | G4: Base year 2050. Combustion only. EU average mix
A5: GHG emission factor | B5: Electricity saved by electricity saving projects | C5: Electricity | D5: 48.8 | E5: tCO2e/TJ | F5: EUCO3232.5 scenario on Member States | G5: Base year 2030. Combustion only. EU average mix
A6: GHG emission factor | B6: Electricity released by 'virtual storage' component | C6: Electricity | D6: 140 | E6: tCO2e/TJ | F6: Based on the EF for combustion of natural gas according to COMMISSION IMPLEMENTING REGULATION (EU) 2018/2066 and a gas turbine with efficiency of 40%.
A7: GHG emission factor | B7: Renewable hydrogen as input | C7: Hydrogen | D7: 0 | E7: tCO2e / t | F7: IF GHG emission methodology
A8: GHG emission factor | B8: Low-carbon hydrogen as input | C8: Hydrogen | D8: 2.4 | E8: tCO2e / t | F8: IF GHG emission methodology
A9: GHG emission factor | B9: Hydrogen not identified as renewable or low-carbon as input | C9: Hydrogen | D9: 6.84 | E9: tCO2e / t | F9: Commission Implementing Regulation (EU) 2021/447 of 12 March 2021 determining revised benchmark values for free allocation of emission allowances for the period from 2021 to 2025 pursuant to Article 10a(2) of Directive 2003/87/EC of the European Parliament and of the Council.
A10: GHG emission factor | B10: Heat as input | C10: Heat | D10: 47.3 | E10: tCO2e/TJ | F10: Commission Implementing Regulation (EU) 2021/447 of 12 March 2021 determining revised benchmark values for free allocation of emission allowances for the period from 2021 to 2025 pursuant to Article 10a(2) of Directive 2003/87/EC of the European Parliament and of the Council.
A11: GHG emission factor | B11: RFNBOs other than hydrogen as inputs | C11: RFNBOs other than hydrogen | D11: 0 | E11: tCO2e/TJ | F11: IF GHG emission methodology
A12: GHG emission factor | B12: Low carbon fuels (LCFs) other than hydrogen as inputs | C12: LCFs other than hydrogen | D12: 20 | E12: tCO2e/TJ | F12: IF GHG emission methodology
A13: GHG emission factor | B13: Combustion emissions for fossil fuel used in processes or as inputs | C13: Crude Oil | D13: 73.54 | E13: tCO2e/TJ | F13: 2006 IPCC Guidelines for National Greenhouse Gas Inventories
A14: GHG emission factor | B14: Combustion emissions for fossil fuel used in processes or as inputs | C14: Jet Kerosene | D14: 71.74 | E14: tCO2e/TJ | F14: 2006 IPCC Guidelines for National Greenhouse Gas Inventories
A15: GHG emission factor | B15: Combustion emissions for fossil fuel used in processes or as inputs | C15: Gas/Diesel Oil | D15: 74.34 | E15: tCO2e/TJ | F15: 2006 IPCC Guidelines for National Greenhouse Gas Inventories
A16: GHG emission factor | B16: Combustion emissions for fossil fuel used in processes or as inputs | C16: Residual Fuel Oil | D16: 77.64 | E16: tCO2e/TJ | F16: 2006 IPCC Guidelines for National Greenhouse Gas Inventories
A17: GHG emission factor | B17: Combustion emissions for fossil fuel used in processes or as inputs | C17: Other Kerosene | D17: 72.14 | E17: tCO2e/TJ | F17: 2006 IPCC Guidelines for National Greenhouse Gas Inventories
... A27: GHG emission factor | B27: Combustion emissions for fossil fuel used in processes or as inputs | C27: Natural gas | D27: 56.2 | E27: tCO2e/TJ | F27: 2006 IPCC Guidelines for National Greenhouse Gas Inventories
A28: GHG emission factor | B28: Embedded emissions for input | C28: N fertilizer | D28: =4571.9 -> 4571.9 | E28: gCO2e/kg | F28: Definition of input data to assess GHG default emissions from biofuels in EU legislation
A29: GHG emission factor | B29: Embedded emissions for input | C29: P2O5 fertilizer | D29: =541.7 -> 541.7 | E29: gCO2e/kg | F29: Definition of input data to assess GHG default emissions from biofuels in EU legislation
A30: GHG emission factor | B30: Embedded emissions for input | C30: K2O fertilizer | D30: =416.7 -> 416.7 | E30: gCO2e/kg | F30: Definition of input data to assess GHG default emissions from biofuels in EU legislation
A31: GHG emission factor | B31: Embedded emissions for input | C31: Aglime (as CaO) | D31: =69.7 -> 69.7 | E31: gCO2e/kg | F31: Definition of input data to assess GHG default emissions from biofuels in EU legislation
A32: GHG emission factor | B32: Embedded emissions for input | C32: Pesticides | D32: =12010.7 -> 12010.7 | E32: gCO2e/kg | F32: Definition of input data to assess GHG default emissions from biofuels in EU legislation
A33: GHG emission factor | B33: Embedded emissions for input | C33: CaO as process chemical | D33: =1193.2 -> 1193.2 | E33: gCO2e/kg | F33: Definition of input data to assess GHG default emissions from biofuels in EU legislation
A34: GHG emission factor | B34: Embedded emissions for input | C34: HCl | D34: =1061.1 -> 1061.1 | E34: gCO2e/kg | F34: Definition of input data to assess GHG default emissions from biofuels in EU legislation
A35: GHG emission factor | B35: Embedded emissions for input | C35: Na2CO3 | D35: =1245.1 -> 1245.1 | E35: gCO2e/kg | F35: Definition of input data to assess GHG default emissions from biofuels in EU legislation
A36: GHG emission factor | B36: Embedded emissions for input | C36: NaCl | D36: =13.3 -> 13.3 | E36: gCO2e/kg | F36: Definition of input data to assess GHG default emissions from biofuels in EU legislation
A37: GHG emission factor | B37: Embedded emissions for input | C37: NaOH | D37: =529.7 -> 529.7 | E37: gCO2e/kg | F37: Definition of input data to assess GHG default emissions from biofuels in EU legislation
A38: GHG emission factor | B38: Embedded emissions for input | C38: Ammonia | D38: =2351.3 -> 2351.3 | E38: gCO2e/kg | F38: Definition of input data to assess GHG default emissions from biofuels in EU legislation
A39: GHG emission factor | B39: Embedded emissions for input | C39: H2SO4 | D39: =217.5 -> 217.5 | E39: gCO2e/kg | F39: Definition of input data to assess GHG default emissions from biofuels in EU legislation
A40: GHG emission factor | B40: Embedded emissions for input | C40: H3PO4 | D40: =3124.7 -> 3124.7 | E40: gCO2e/kg | F40: Definition of input data to assess GHG default emissions from biofuels in EU legislation
A41: GHG emission factor | B41: Embedded emissions for input | C41: Cyclohexane | D41: =723 -> 723 | E41: gCO2e/kg | F41: Definition of input data to assess GHG default emissions from biofuels in EU legislation
A42: GHG emission factor | B42: Embedded emissions for input | C42: Lubricants | D42: =947 -> 947 | E42: gCO2e/kg | F42: Definition of input data to assess GHG default emissions from biofuels in EU legislation
A43: GHG emission factor | B43: Embedded emissions for input | C43: Alpha-amylase | D43: =1000 -> 1000 | E43: gCO2e/kg | F43: Definition of input data to assess GHG default emissions from biofuels in EU legislation
A44: GHG emission factor | B44: Embedded emissions for input | C44: Gluco-amylase | D44: =7500 -> 7500 | E44: gCO2e/kg | F44: Definition of input data to assess GHG default emissions from biofuels in EU legislation
A45: GHG emission factor | B45: Embedded emissions for input | C45: Na(CH3O) | D45: =2425.5 -> 2425.5 | E45: gCO2e/kg | F45: Definition of input data to assess GHG default emissions from biofuels in EU legislation
A46: GHG emission factor | B46: Embedded emissions for input | C46: n-hexane | D46: =12.5 -> 12.5 | E46: tCO2e/TJ | F46: Definition of input data to assess GHG default emissions from biofuels in EU legislation
A47: GHG emission factor | B47: Embedded emissions for input | C47: Methanol | D47: 28.2 | E47: tCO2e/TJ | F47: Definition of input data to assess GHG default emissions from biofuels in EU legislation
A48: GHG emission factor | B48: Embedded emissions for input | C48: KOH | D48: =419.1 -> 419.1 | E48: gCO2e/kg | F48: Definition of input data to assess GHG default emissions from biofuels in EU legislation
A49: GHG emission factor | B49: Embedded emissions for input | C49: N2 | D49: =56.4 -> 56.4 | E49: gCO2e/kg | F49: Definition of input data to assess GHG default emissions from biofuels in EU legislation
...

Sheet Assumptions
A1: Assumptions
A2: Data / Assumption | B2: Value | C2: Unit of measure | D2: Description | E2: Source of data | F2: Comment | G2: Data traceability
G3: Parameter to be monitored / not monitored | H3: Data source for monitoring | I3: Reliability | J3: Monitoring frequency | K3: Department responsible for collection and archiving | L3: Monitoring approach and equipment used, including details on accuracy and calibration | M3: QA/QC Procedures | N3: Additional description of the monitoring system

Sheet CC credit overview
A1: Tool to support the calculation of CCS/U credit under the Innovation Fund
A3: Introduction to the CC_credit calculation tool
A4: This part of the tool supports the calculation of the credit (negative emissions) for projects with Carbon Capture and Storage (CCS) or Carbon Capture and Use (CCU) elements. The credit is included in the GHG avoidance calculations on the 'Summary per year' and 'Summary' sheets. In the unusual case that the reference scenario includes an element of carbon capture and storage or utilisation, then applicants should adapt the 'CC credit_calculation' sheet to separately calculate a carbon capture credit term for the project scenario and a carbon capture credit term for the reference scenario. Then, an overall carbon capture credit shall be defined as the difference between the carbon capture credit in the project scenario and the carbon credit in the reference scenario, for inclusion in the GHG avoidance calculations in the 'Summary per year' and 'Summary' sheets. Project emissions due to transportation by road and maritime modals shall be quantified based on distance travelled data, type of modal and load. For projects submitted to the IF in a small scale call, project emissions due to transportation by road, rail and maritime modals can be disregarded from the calculation of the GHG emissions avoidance, if the total distance between the point of capture and the point of storage is inferior to 5,000 kilometres.
A6: For further detailed information on how to do the calculation and on all conditions linked to the application and grant award, please refer to the call text and the Methodology for GHG Emission Avoidance Calculation. This tool is provided only as support. In case of divergence of the information or formulas between here and the call text or methodology, the call text and methodology take precedence.
A8: Definitions
A10: CCcredit | B10: Carbon capture credit. It defines the net GHG benefit delivered by a project through CO2 storage or utilisation in year y. It is calculated as a positive term for inclusion in equation [1.1].
A11: CCstorage,y | B11: Amount of CO2 that is injected for permanent storage in year y, in tonnes CO2.
A12: CCuse,y | B12: Amount of CO2 that is incorporated into products in year y, in tonnes CO2e.
A13: CCcapture,y | B13: GHG emissions from CO2 capture activities, in tonnes CO2e.
A14: CCinjection,y | B14: GHG emissions from injection and geological storage of CO2 in a storage site.
A15: CCEHR,y | B15: For projects in which CO2 injection and storage is associated with enhanced hydrocarbon recovery, emissions consistent with stoichiometric combustion of the associated fraction of the produced hydrocarbons.
A16: CCpipeline,y | B16: GHG emissions from transport of CO2 by pipelines, in tonnes CO2e.
A17: CCtransport,y | B17: GHG emissions from transport of CO2 via road, rail or maritime modals in year y.

Sheet CC credit calculation
A1: CC credit Summary
A2: This summary table uses the sumif function to add emissions from rows with each label. This requires the row labels below to exactly match the row labels used here.
A3: If adding, removing or moving rows applicants should check that the total emissions for each label are still correctly summed.
A5: Row Labels | B5: Sum of t CO2e | C5: Automated checks
A6: CCuse,y | B6: =SUMIF($A$23:$A$36,$A6,$AB$23:$AB$36) -> 0
A7: CCstorage,y | B7: =SUMIF($A$23:$A$36,$A7,$AB$23:$AB$36) -> 0
A8: CCcapture,y | B8: =SUMIF($A$23:$A$36,$A8,$AB$23:$AB$36) -> 0
A9: CCpipeline,y | B9: =SUMIF($A$23:$A$36,$A9,$AB$23:$AB$36) -> 0
A10: CCinjection,y | B10: =SUMIF($A$23:$A$36,$A10,$AB$23:$AB$36) -> 0
A11: CCtransport,road,y | B11: =SUMIF($A$23:$A$36,$A11,$AB$23:$AB$36) -> 0
A12: CCtransport,maritime,y | B12: =SUMIF($A$23:$A$36,$A12,$AB$23:$AB$36) -> 0
A13: CCtransport,rail,y | B13: =SUMIF($A$23:$A$36,$A13,$AB$23:$AB$36) -> 0
A14: Grand Total | B14: =SUM(B6:B7)-SUM(B8:B13) -> 0 | C14: Check that the horizontal and vertical sums are consistent | D14: =+ IF(AND(ROUND(B14,2)=ROUND(AB21,2),ROUND(B14,2)=ROUND(SUM(R21:AA21),2)),"OK","ERR") -> OK
A16: CC credit Calculation
A18: Operational data | Q18: GHG Emissions | AD18: Data traceability
